Workbook

Sheet April 25
A1: April | B1: Shopify
A3: Products | B3: Total revenue | C3: Total expense | D3: Total P/L | E3: Profit % | F3: P/pcs | G3: Ad spent | H3: Total orders | I3: Shipped | J3: Product expense | K3: Delivered | L3: Shipping charges | M3: RTO | N3: In-transit | O3: RTO% | P3: Shipped% | Q3: Delivered % | R3: CPD | S3: Cancellation %
A4: V1 | B4: 584117 | C4: =G4+J4+L4 -> 186864 | D4: =B4-C4 -> 397253 | E4: =D4/B4*100 -> 68.009149 | F4: =D4/K4 -> 704.34929 | H4: 607 | I4: 588 | J4: =250*K4 -> 141000 | K4: 564 | L4: =I4*78 -> 45864 | M4: =I4-K4-N4 -> 24 | O4: =M4/I4*100 -> 4.0816327 | P4: =I4/H4*100 -> 96.869852 | Q4: =K4/I4*100 -> 95.918367 | R4: =G4/K4 -> 0 | S4: =100-P4 -> 3.1301483 | T4: =B4/B21*100 -> 9.6820739
A5: V1- P of 2 | B5: 23288 | C5: =G5+J5+L5 -> 6936 | D5: =B5-C5 -> 16352 | E5: =D5/B5*100 -> 70.21642 | F5: =D5/K5 -> 1362.6667 | H5: 13 | I5: 12 | J5: =500*K5 -> 6000 | K5: 12 | L5: =I5*78 -> 936 | M5: =I5-K5-N5 -> 0 | O5: =M5/I5*100 -> 0 | P5: =I5/H5*100 -> 92.307692 | Q5: =K5/I5*100 -> 100 | R5: =G5/K5 -> 0 | S5: =100-P5 -> 7.6923077 | T5: =B5/B21*100 -> 0.38601194
A6: V2 | B6: 849827 | C6: =G6+J6+L6 -> 297662 | D6: =B6-C6 -> 552165 | E6: =D6/B6*100 -> 64.973812 | F6: =D6/K6 -> 802.56541 | H6: 751 | I6: 729 | J6: =350*K6 -> 240800 | K6: 688 | L6: =I6*78 -> 56862 | M6: =I6-K6-N6 -> 41 | O6: =M6/I6*100 -> 5.6241427 | P6: =I6/H6*100 -> 97.070573 | Q6: =K6/I6*100 -> 94.375857 | R6: =G6/K6 -> 0 | S6: =100-P6 -> 2.9294274 | T6: =B6/B21*100 -> 14.086369
A7: V2- P of 2 | B7: 44780 | C7: =G7+J7+L7 -> 14860 | D7: =B7-C7 -> 29920 | E7: =D7/B7*100 -> 66.815543 | F7: =D7/K7 -> 1574.7368 | H7: 20 | I7: 20 | J7: =700*K7 -> 13300 | K7: 19 | L7: =I7*78 -> 1560 | M7: =I7-K7-N7 -> 1 | O7: =M7/I7*100 -> 5 | P7: =I7/H7*100 -> 100 | Q7: =K7/I7*100 -> 95 | R7: =G7/K7 -> 0 | S7: =100-P7 -> 0 | T7: =B7/B21*100 -> 0.74225415
A8: V3 | B8: 201900 | C8: =G8+J8+L8 -> 88770 | D8: =B8-C8 -> 113130 | E8: =D8/B8*100 -> 56.032689 | F8: =D8/K8 -> 992.36842 | H8: 122 | I8: 115 | J8: =700*K8 -> 79800 | K8: 114 | L8: =I8*78 -> 8970 | M8: =I8-K8-N8 -> 1 | O8: =M8/I8*100 -> 0.86956522 | P8: =I8/H8*100 -> 94.262295 | Q8: =K8/I8*100 -> 99.130435 | R8: =G8/K8 -> 0 | S8: =100-P8 -> 5.7377049 | T8: =B8/B21*100 -> 3.3466082
A9: V4 | B9: 131285 | C9: =G9+J9+L9 -> 83024 | D9: =B9-C9 -> 48261 | E9: =D9/B9*100 -> 36.760483 | F9: =D9/K9 -> 163.59661 | H9: 322 | I9: 308 | J9: =200*K9 -> 59000 | K9: 295 | L9: =I9*78 -> 24024 | M9: =I9-K9-N9 -> 13 | O9: =M9/I9*100 -> 4.2207792 | P9: =I9/H9*100 -> 95.652174 | Q9: =K9/I9*100 -> 95.779221 | R9: =G9/K9 -> 0 | S9: =100-P9 -> 4.3478261 | T9: =B9/B21*100 -> 2.1761241
A10: V4- P of 2 | B10: 51303 | C10: =G10+J10+L10 -> 29236 | D10: =B10-C10 -> 22067 | E10: =D10/B10*100 -> 43.013079 | F10: =D10/K10 -> 361.7541 | H10: 66 | I10: 62 | J10: =400*K10 -> 24400 | K10: 61 | L10: =I10*78 -> 4836 | M10: =I10-K10-N10 -> 1 | O10: =M10/I10*100 -> 1.6129032 | P10: =I10/H10*100 -> 93.939394 | Q10: =K10/I10*100 -> 98.387097 | R10: =G10/K10 -> 0 | S10: =100-P10 -> 6.0606061 | T10: =B10/B21*100 -> 0.85037661
A11: V5 | B11: 74759 | C11: =G11+J11+L11 -> 24506 | D11: =B11-C11 -> 50253 | E11: =D11/B11*100 -> 67.22 | F11: =D11/K11 -> 679.09459 | H11: 83 | I11: 77 | J11: =250*K11 -> 18500 | K11: 74 | L11: =I11*78 -> 6006 | M11: =I11-K11-N11 -> 3 | O11: =M11/I11*100 -> 3.8961039 | P11: =I11/H11*100 -> 92.771084 | Q11: =K11/I11*100 -> 96.103896 | R11: =G11/K11 -> 0 | S11: =100-P11 -> 7.2289157 | T11: =B11/B21*100 -> 1.2391732
A12: V6 | B12: 908265 | C12: =G12+J12+L12 -> 343618 | D12: =B12-C12 -> 564647 | E12: =D12/B12*100 -> 62.167649 | F12: =D12/K12 -> 713.83944 | H12: 882 | I12: 856 | J12: =350*K12 -> 276850 | K12: 791 | L12: =I12*78 -> 66768 | M12: =I12-K12-N12 -> 65 | O12: =M12/I12*100 -> 7.5934579 | P12: =I12/H12*100 -> 97.052154 | Q12: =K12/I12*100 -> 92.406542 | R12: =G12/K12 -> 0 | S12: =100-P12 -> 2.9478458 | T12: =B12/B21*100 -> 15.055013
A13: V6- P of 2 | B13: 40608 | C13: =G13+J13+L13 -> 14782 | D13: =B13-C13 -> 25826 | E13: =D13/B13*100 -> 63.598306 | F13: =D13/K13 -> 1359.2632 | H13: 20 | I13: 19 | J13: =700*K13 -> 13300 | K13: 19 | L13: =I13*78 -> 1482 | M13: =I13-K13-N13 -> 0 | O13: =M13/I13*100 -> 0 | P13: =I13/H13*100 -> 95 | Q13: =K13/I13*100 -> 100 | R13: =G13/K13 -> 0 | S13: =100-P13 -> 5 | T13: =B13/B21*100 -> 0.67310086
A14: V7 | B14: 113826 | C14: =G14+J14+L14 -> 56612 | D14: =B14-C14 -> 57214 | E14: =D14/B14*100 -> 50.264439 | F14: =D14/K14 -> 589.83505 | H14: 110 | I14: 104 | J14: =500*K14 -> 48500 | K14: 97 | L14: =I14*78 -> 8112 | M14: =I14-K14-N14 -> 7 | O14: =M14/I14*100 -> 6.7307692 | P14: =I14/H14*100 -> 94.545455 | Q14: =K14/I14*100 -> 93.269231 | R14: =G14/K14 -> 0 | S14: =100-P14 -> 5.4545455 | T14: =B14/B21*100 -> 1.8867312
A15: V8 | B15: 145054 | C15: =G15+J15+L15 -> 64264 | D15: =B15-C15 -> 80790 | E15: =D15/B15*100 -> 55.696499 | F15: =D15/K15 -> 985.2439 | H15: 102 | I15: 88 | J15: =700*K15 -> 57400 | K15: 82 | L15: =I15*78 -> 6864 | M15: =I15-K15-N15 -> 6 | O15: =M15/I15*100 -> 6.8181818 | P15: =I15/H15*100 -> 86.27451 | Q15: =K15/I15*100 -> 93.181818 | R15: =G15/K15 -> 0 | S15: =100-P15 -> 13.72549 | T15: =B15/B21*100 -> 2.4043531
A16: V9 | B16: 2414163 | C16: =G16+J16+L16 -> 1123392 | D16: =B16-C16 -> 1290771 | E16: =D16/B16*100 -> 53.466605 | F16: =D16/K16 -> 1129.2835 | H16: 1277 | I16: 1214 | J16: =900*K16 -> 1028700 | K16: 1143 | L16: =I16*78 -> 94692 | M16: =I16-K16-N16 -> 71 | O16: =M16/I16*100 -> 5.8484349 | P16: =I16/H16*100 -> 95.066562 | Q16: =K16/I16*100 -> 94.151565 | R16: =G16/K16 -> 0 | S16: =100-P16 -> 4.9334377 | T16: =B16/B21*100 -> 40.016135
A17: V9 P of 2 | B17: 147995 | C17: =G17+J17+L17 -> 73476 | D17: =B17-C17 -> 74519 | E17: =D17/B17*100 -> 50.352377 | F17: =D17/K17 -> 1910.7436 | H17: 45 | I17: 42 | J17: =1800*K17 -> 70200 | K17: 39 | L17: =I17*78 -> 3276 | M17: =I17-K17-N17 -> 3 | O17: =M17/I17*100 -> 7.1428571 | P17: =I17/H17*100 -> 93.333333 | Q17: =K17/I17*100 -> 92.857143 | R17: =G17/K17 -> 0 | S17: =100-P17 -> 6.6666667 | T17: =B17/B21*100 -> 2.4531019
A18: V6-V2 Combo | B18: 142122 | C18: =G18+J18+L18 -> 50648 | D18: =B18-C18 -> 91474 | E18: =D18/B18*100 -> 64.363012 | F18: =D18/K18 -> 1407.2923 | H18: 71 | I18: 66 | J18: =K18*700 -> 45500 | K18: 65 | L18: =I18*78 -> 5148 | M18: =I18-K18-N18 -> 1 | O18: =M18/I18*100 -> 1.5151515 | P18: =I18/H18*100 -> 92.957746 | Q18: =K18/I18*100 -> 98.484848 | R18: =G18/K18 -> 0 | S18: =100-P18 -> 7.0422535 | T18: =B18/B21*100 -> 2.3557536
A19: V6-V4 Combo | B19: 22508 | C19: =G19+J19+L19 -> 7536 | D19: =B19-C19 -> 14972 | E19: =D19/B19*100 -> 66.518571 | F19: =D19/K19 -> 1247.6667 | H19: 13 | I19: 12 | J19: =K19*550 -> 6600 | K19: 12 | L19: =I19*78 -> 936 | M19: =I19-K19-N19 -> 0 | O19: =M19/I19*100 -> 0 | P19: =I19/H19*100 -> 92.307692 | Q19: =K19/I19*100 -> 100 | R19: =G19/K19 -> 0 | S19: =100-P19 -> 7.6923077 | T19: =B19/B21*100 -> 0.37308299
A20: Busy Book | B20: 137174 | C20: =G20+J20+L20 -> 74507 | D20: =B20-C20 -> 62667 | E20: =D20/B20*100 -> 45.684313 | F20: =D20/K20 -> 238.27757 | H20: 264 | I20: 264 | J20: =K20*205 -> 53915 | K20: 263 | L20: =I20*78 -> 20592 | M20: =I20-K20-N20 -> 1 | O20: =M20/I20*100 -> 0.37878788 | P20: =I20/H20*100 -> 100 | Q20: =K20/I20*100 -> 99.621212 | R20: =G20/K20 -> 0 | S20: =100-P20 -> 0 | T20: =B20/B21*100 -> 2.2737376
A21: Total | B21: =SUM(B4:B20) -> 6032974 | D21: =SUM(D4:D20) -> 3492281 | G21: 3500724 | H21: =SUM(H4:H20) -> 4768 | I21: =SUM(I4:I20) -> 4576 | J21: =SUM(J4:J20) -> 2183765 | K21: =SUM(K4:K20) -> 4338 | L21: =SUM(L4:L20) -> 356928 | M21: =SUM(M4:M20) -> 238 | N21: =SUM(N4:N20) -> 0 | R21: =SUM(R4:R20) -> 0
A24: Shopify | D24: Blended
A25: Total Revenue | B25: =B21 -> 6032974 | D25: COGS | E25: =B26/K21 -> 503.40364
A26: COGS | B26: =J21 -> 2183765 | C26: 0.36 | D26: CAC | E26: =B28/K21 -> 806.99032
A27: Logistics | B27: =L21 -> 356928 | C27: 0.06 | D27: Logistics | E27: =L21/K21 -> 82.279391
A28: Marketing | B28: =G21 -> 3500724 | C28: 0.58 | D28: AOV | E28: =B25/K21 -> 1390.7271
A29: P&L | B29: =B25-(B26+B27+B28) -> -8443
A30: P&L %
A33: April | B33: Amazon
B35: Total revenue | C35: Total expense | D35: Total P/L | E35: Profit % | F35: P/pcs | G35: Total orders | H35: Product expense | I35: Delivered | J35: Return | K35: Amazon expense | L35: RTO% | M35: Only Ad spend | N35: Return GMV
A36: V1 | B36: =897486+37687.24+15175.92 -> 950349.16 | C36: =K36+H36 -> 586466.44 | D36: =B36-C36 -> 363882.72 | E36: =D36/B36*100 -> 38.289371 | F36: =D36/I36 -> 378.65007 | G36: =1018+37+10 -> 1065 | H36: =250*I36 -> 240250 | I36: =909+32+20 -> 961 | J36: =G36-I36 -> 104 | K36: =330908.99+13077.61+2229.84 -> 346216.44 | L36: =J36/G36*100 -> 9.7652582 | N36: =J36*999 -> 103896 | O36: =B36/M36 -> #DIV/0! | P36: =B36/B51*100 -> 33.651225
A37: V2 | B37: =682999+28950.52 -> 711949.52 | C37: =K37+H37 -> 345782.34 | D37: =B37-C37 -> 366167.18 | E37: =D37/B37*100 -> 51.431621 | F37: =D37/I37 -> 617.4826 | G37: =608+26 -> 634 | H37: =350*I37 -> 207550 | I37: =571+22 -> 593 | J37: =G37-I37 -> 41 | K37: =128290.96 + 9941.38 -> 138232.34 | L37: =J37/G37*100 -> 6.466877 | M37: 0 | N37: =J37*1119 -> 45879 | O37: =B37/M37 -> #DIV/0! | P37: =B37/B51*100 -> 25.209654
A38: V3 | B38: =8495 -> 8495 | C38: =K38+H38 -> 5781.95 | D38: =B38-C38 -> 2713.05 | E38: =D38/B38*100 -> 31.937022 | F38: =D38/I38 -> 542.61 | G38: 5 | H38: =900*I38 -> 4500 | I38: 5 | J38: =G38-I38 -> 0 | K38: =1281.95 -> 1281.95 | L38: =J38/G38*100 -> 0 | M38: 0 | N38: =J38*1799 -> 0 | O38: =B38/M38 -> #DIV/0! | P38: =B38/B51*100 -> 0.30080224
A39: V4 | B39: =401764+7122.92 -> 408886.92 | C39: =K39+H39 -> 351973.5 | D39: =B39-C39 -> 56913.42 | E39: =D39/B39*100 -> 13.91911 | F39: =D39/I39 -> 65.872014 | G39: =914+11 -> 925 | H39: =220*I39 -> 190080 | I39: =11+853 -> 864 | J39: =G39-I39 -> 61 | K39: =160673.89 + 1219.61 -> 161893.5 | L39: =J39/G39*100 -> 6.5945946 | M39: 0 | N39: =J39*499 -> 30439 | O39: =B39/M39 -> #DIV/0! | P39: =B39/B51*100 -> 14.478411
A40: V5 | B40: =5836.96+52653 -> 58489.96 | C40: =K40+H40 -> 57243.72 | D40: =B40-C40 -> 1246.24 | E40: =D40/B40*100 -> 2.1306905 | F40: =D40/I40 -> 19.4725 | G40: =67+10 -> 77 | H40: =250*I40 -> 16000 | I40: =59+5 -> 64 | J40: =G40-I40 -> 13 | K40: =9362.66+31881.06 -> 41243.72 | L40: =J40/G40*100 -> 16.883117 | M40: 0 | N40: =J40*1049 -> 13637 | O40: =B40/M40 -> #DIV/0! | P40: =B40/B51*100 -> 2.0710902
A41: V6 | B41: =8994+224817 -> 233811 | C41: =K41+H41 -> 153158.13 | D41: =B41-C41 -> 80652.87 | E41: =D41/B41*100 -> 34.4949 | F41: =D41/I41 -> 389.62739 | G41: =245+7 -> 252 | H41: =320*I41 -> 66240 | I41: =201+6 -> 207 | J41: =G41-I41 -> 45 | K41: =2992.3+83925.83 -> 86918.13 | L41: =J41/G41*100 -> 17.857143 | M41: 0 | N41: =J41*1249 -> 56205 | O41: =B41/M41 -> #DIV/0! | P41: =B41/B51*100 -> 8.2790904
A42: V7 | B42: =10054.48+57064 -> 67118.48 | C42: =K42+H42 -> 58514.81 | D42: =B42-C42 -> 8603.67 | E42: =D42/B42*100 -> 12.818631 | F42: =D42/I42 -> 191.19267 | G42: =37+10 -> 47 | H42: =500*I42 -> 22500 | I42: =37+8 -> 45 | J42: =G42-I42 -> 2 | K42: =28226.67 + 7788.14 -> 36014.81 | L42: =J42/G42*100 -> 4.2553191 | M42: 0 | N42: =J42*1349 -> 2698 | O42: =B42/M42 -> #DIV/0! | P42: =B42/B51*100 -> 2.3766203
A43: V8 | B43: 0 | C43: =K43+H43 -> 0 | D43: =B43-C43 -> 0 | E43: =D43/B43*100 -> #DIV/0! | F43: =D43/I43 -> #DIV/0! | G43: 0 | H43: =800*I43 -> 0 | I43: 0 | J43: =G43-I43 -> 0 | K43: 0 | L43: =J43/G43*100 -> #DIV/0! | M43: 0 | N43: =J43*1899 -> 0 | O43: =B43/M43 -> #DIV/0! | P43: =B43/B51*100 -> 0
A44: V9 | B44: =173817+119322.96 -> 293139.96 | C44: =K44+H44 -> 197022.87 | D44: =B44-C44 -> 96117.09 | E44: =D44/B44*100 -> 32.788805 | F44: =D44/I44 -> 691.48986 | G44: =100+62 -> 162 | H44: =1000*I44 -> 139000 | I44: =84+55 -> 139 | J44: =G44-I44 -> 23 | K44: =33042.98+24979.89 -> 58022.87 | L44: =J44/G44*100 -> 14.197531 | M44: 0 | N44: =J44*1999 -> 45977 | O44: =B44/M44 -> #DIV/0! | P44: =B44/B51*100 -> 10.379889
A45: BB | B45: =50716 -> 50716 | C45: =K45+H45 -> 41926.86 | D45: =B45-C45 -> 8789.14 | E45: =D45/B45*100 -> 17.330113 | F45: =D45/I45 -> 101.0246 | G45: 92 | H45: =200*I45 -> 17400 | I45: 87 | J45: =G45-I45 -> 5 | K45: =24526.86 -> 24526.86 | L45: =J45/G45*100 -> 5.4347826 | M45: 0 | N45: =J45*599 -> 2995 | O45: =B45/M45 -> #DIV/0! | P45: =B45/B51*100 -> 1.7958195
A46: V1V4 | B46: 0 | C46: =K46+H46 -> 0 | D46: =B46-C46 -> 0 | E46: =D46/B46*100 -> #DIV/0! | F46: =D46/I46 -> #DIV/0! | G46: 0 | H46: =(270+220)*I46 -> 0 | I46: 0 | J46: =G46-I46 -> 0 | K46: 0 | L46: =J46/G46*100 -> #DIV/0! | M46: 0 | O46: =B46/M46 -> #DIV/0! | P46: =B46/B51*100 -> 0
...

Sheet May 25
A1: May | B1: Shopify
A3: Products | B3: Total revenue | C3: Total expense | D3: Total P/L | E3: Profit % | F3: P/pcs | G3: Ad spent | H3: Total orders | I3: Shipped | J3: Product expense | K3: Delivered | L3: Shipping charges | M3: RTO | N3: In-transit | O3: RTO% | P3: Shipped% | Q3: Delivered % | R3: CPD | S3: Cancellation %
A4: V1 | B4: 549323 | C4: =G4+J4+L4 -> 189912 | D4: =B4-C4 -> 359411 | E4: =D4/B4*100 -> 65.42799 | F4: =D4/K4 -> 660.68199 | H4: 594 | I4: 586 | J4: =250*K4 -> 136000 | K4: 544 | L4: =I4*92 -> 53912 | M4: =I4-K4-N4 -> 42 | O4: =M4/I4*100 -> 7.1672355 | P4: =I4/H4*100 -> 98.653199 | Q4: =K4/I4*100 -> 92.832765 | R4: =G4/K4 -> 0 | S4: =100-P4 -> 1.3468013
A5: V1- P of 2 | B5: 11752 | C5: =G5+J5+L5 -> 3552 | D5: =B5-C5 -> 8200 | E5: =D5/B5*100 -> 69.775357 | F5: =D5/K5 -> 1366.6667 | H5: 6 | I5: 6 | J5: =500*K5 -> 3000 | K5: 6 | L5: =I5*92 -> 552 | M5: =I5-K5-N5 -> 0 | O5: =M5/I5*100 -> 0 | P5: =I5/H5*100 -> 100 | Q5: =K5/I5*100 -> 100 | R5: =G5/K5 -> 0 | S5: =100-P5 -> 0
A6: V2 | B6: 460600 | C6: =G6+J6+L6 -> 173096 | D6: =B6-C6 -> 287504 | E6: =D6/B6*100 -> 62.419453 | F6: =D6/K6 -> 744.82902 | H6: 419 | I6: 413 | J6: =350*K6 -> 135100 | K6: 386 | L6: =I6*92 -> 37996 | M6: =I6-K6-N6 -> 27 | O6: =M6/I6*100 -> 6.5375303 | P6: =I6/H6*100 -> 98.568019 | Q6: =K6/I6*100 -> 93.46247 | R6: =G6/K6 -> 0 | S6: =100-P6 -> 1.4319809
A7: V2- P of 2 | B7: 8758 | C7: =G7+J7+L7 -> 3168 | D7: =B7-C7 -> 5590 | E7: =D7/B7*100 -> 63.827358 | F7: =D7/K7 -> 1397.5 | H7: 5 | I7: 4 | J7: =700*K7 -> 2800 | K7: 4 | L7: =I7*92 -> 368 | M7: =I7-K7-N7 -> 0 | O7: =M7/I7*100 -> 0 | P7: =I7/H7*100 -> 80 | Q7: =K7/I7*100 -> 100 | R7: =G7/K7 -> 0 | S7: =100-P7 -> 20
A8: V3 | B8: 33818 | C8: =G8+J8+L8 -> 16632 | D8: =B8-C8 -> 17186 | E8: =D8/B8*100 -> 50.81909 | F8: =D8/K8 -> 818.38095 | H8: 22 | I8: 21 | J8: =700*K8 -> 14700 | K8: 21 | L8: =I8*92 -> 1932 | M8: =I8-K8-N8 -> 0 | O8: =M8/I8*100 -> 0 | P8: =I8/H8*100 -> 95.454545 | Q8: =K8/I8*100 -> 100 | R8: =G8/K8 -> 0 | S8: =100-P8 -> 4.5454545
A9: V4 | B9: 170818 | C9: =G9+J9+L9 -> 124804 | D9: =B9-C9 -> 46014 | E9: =D9/B9*100 -> 26.937442 | F9: =D9/K9 -> 108.78014 | H9: 439 | I9: 437 | J9: =200*K9 -> 84600 | K9: 423 | L9: =I9*92 -> 40204 | M9: =I9-K9-N9 -> 14 | O9: =M9/I9*100 -> 3.2036613 | P9: =I9/H9*100 -> 99.544419 | Q9: =K9/I9*100 -> 96.796339 | R9: =G9/K9 -> 0 | S9: =100-P9 -> 0.45558087
A10: V4- P of 2 | B10: 41284 | C10: =G10+J10+L10 -> 25092 | D10: =B10-C10 -> 16192 | E10: =D10/B10*100 -> 39.221006 | F10: =D10/K10 -> 317.4902 | H10: 52 | I10: 51 | J10: =400*K10 -> 20400 | K10: 51 | L10: =I10*92 -> 4692 | M10: =I10-K10-N10 -> 0 | O10: =M10/I10*100 -> 0 | P10: =I10/H10*100 -> 98.076923 | Q10: =K10/I10*100 -> 100 | R10: =G10/K10 -> 0 | S10: =100-P10 -> 1.9230769
A11: V5 | B11: 64141 | C11: =G11+J11+L11 -> 22520 | D11: =B11-C11 -> 41621 | E11: =D11/B11*100 -> 64.889852 | F11: =D11/K11 -> 586.21127 | H11: 91 | I11: 75 | J11: =220*K11 -> 15620 | K11: 71 | L11: =I11*92 -> 6900 | M11: =I11-K11-N11 -> 4 | O11: =M11/I11*100 -> 5.3333333 | P11: =I11/H11*100 -> 82.417582 | Q11: =K11/I11*100 -> 94.666667 | R11: =G11/K11 -> 0 | S11: =100-P11 -> 17.582418
A12: V6 | B12: 852560 | C12: =G12+J12+L12 -> 327316 | D12: =B12-C12 -> 525244 | E12: =D12/B12*100 -> 61.607863 | F12: =D12/K12 -> 717.54645 | H12: 802 | I12: 773 | J12: =350*K12 -> 256200 | K12: 732 | L12: =I12*92 -> 71116 | M12: =I12-K12-N12 -> 41 | O12: =M12/I12*100 -> 5.3040103 | P12: =I12/H12*100 -> 96.38404 | Q12: =K12/I12*100 -> 94.69599 | R12: =G12/K12 -> 0 | S12: =100-P12 -> 3.6159601
A13: V6- P of 2 | B13: 22186 | C13: =G13+J13+L13 -> 7920 | D13: =B13-C13 -> 14266 | E13: =D13/B13*100 -> 64.301812 | F13: =D13/K13 -> 1426.6 | H13: 10 | I13: 10 | J13: =700*K13 -> 7000 | K13: 10 | L13: =I13*92 -> 920 | M13: =I13-K13-N13 -> 0 | O13: =M13/I13*100 -> 0 | P13: =I13/H13*100 -> 100 | Q13: =K13/I13*100 -> 100 | R13: =G13/K13 -> 0 | S13: =100-P13 -> 0
A14: V7 | B14: 111760 | C14: =G14+J14+L14 -> 64304 | D14: =B14-C14 -> 47456 | E14: =D14/B14*100 -> 42.462419 | F14: =D14/K14 -> 439.40741 | H14: 113 | I14: 112 | J14: =500*K14 -> 54000 | K14: 108 | L14: =I14*92 -> 10304 | M14: =I14-K14-N14 -> 4 | O14: =M14/I14*100 -> 3.5714286 | P14: =I14/H14*100 -> 99.115044 | Q14: =K14/I14*100 -> 96.428571 | R14: =G14/K14 -> 0 | S14: =100-P14 -> 0.88495575
A15: V8 | B15: 25724 | C15: =G15+J15+L15 -> 11880 | D15: =B15-C15 -> 13844 | E15: =D15/B15*100 -> 53.817447 | F15: =D15/K15 -> 922.93333 | H15: 16 | I15: 15 | J15: =700*K15 -> 10500 | K15: 15 | L15: =I15*92 -> 1380 | M15: =I15-K15-N15 -> 0 | O15: =M15/I15*100 -> 0 | P15: =I15/H15*100 -> 93.75 | Q15: =K15/I15*100 -> 100 | R15: =G15/K15 -> 0 | S15: =100-P15 -> 6.25
A16: V9 | B16: 1250257 | C16: =G16+J16+L16 -> 665312 | D16: =B16-C16 -> 584945 | E16: =D16/B16*100 -> 46.785981 | F16: =D16/K16 -> 880.94127 | H16: 752 | I16: 736 | J16: =900*K16 -> 597600 | K16: 664 | L16: =I16*92 -> 67712 | M16: =I16-K16-N16 -> 72 | O16: =M16/I16*100 -> 9.7826087 | P16: =I16/H16*100 -> 97.87234 | Q16: =K16/I16*100 -> 90.217391 | R16: =G16/K16 -> 0 | S16: =100-P16 -> 2.1276596
A17: V9 P of 2 | B17: =46937+4211 -> 51148 | C17: =G17+J17+L17 -> 28380 | D17: =B17-C17 -> 22768 | E17: =D17/B17*100 -> 44.513959 | F17: =D17/K17 -> 1517.8667 | H17: 15 | I17: 15 | J17: =1800*K17 -> 27000 | K17: 15 | L17: =I17*92 -> 1380 | M17: =I17-K17-N17 -> 0 | O17: =M17/I17*100 -> 0 | P17: =I17/H17*100 -> 100 | Q17: =K17/I17*100 -> 100 | R17: =G17/K17 -> 0 | S17: =100-P17 -> 0
A18: V6-V2 Combo | B18: 134699 | C18: =G18+J18+L18 -> 50688 | D18: =B18-C18 -> 84011 | E18: =D18/B18*100 -> 62.369431 | F18: =D18/K18 -> 1312.6719 | H18: 65 | I18: 64 | J18: =K18*700 -> 44800 | K18: 64 | L18: =I18*92 -> 5888 | M18: =I18-K18-N18 -> 0 | O18: =M18/I18*100 -> 0 | P18: =I18/H18*100 -> 98.461538 | Q18: =K18/I18*100 -> 100 | R18: =G18/K18 -> 0 | S18: =100-P18 -> 1.5384615
A19: V6-V4 Combo | B19: 27054 | C19: =G19+J19+L19 -> 9738 | D19: =B19-C19 -> 17316 | E19: =D19/B19*100 -> 64.005323 | F19: =D19/K19 -> 1332 | H19: 15 | I19: 14 | J19: =K19*650 -> 8450 | K19: 13 | L19: =I19*92 -> 1288 | M19: =I19-K19-N19 -> 1 | O19: =M19/I19*100 -> 7.1428571 | P19: =I19/H19*100 -> 93.333333 | Q19: =K19/I19*100 -> 92.857143 | R19: =G19/K19 -> 0 | S19: =100-P19 -> 6.6666667
A20: Busy Book | B20: 162000 | C20: =G20+J20+L20 -> 102680 | D20: =B20-C20 -> 59320 | E20: =D20/B20*100 -> 36.617284 | F20: =D20/K20 -> 227.27969 | H20: 265 | I20: 265 | J20: =K20*300 -> 78300 | K20: 261 | L20: =I20*92 -> 24380 | M20: =I20-K20-N20 -> 4 | O20: =M20/I20*100 -> 1.509434 | P20: =I20/H20*100 -> 100 | Q20: =K20/I20*100 -> 98.490566 | R20: =G20/K20 -> 0 | S20: =100-P20 -> 0
A21: Total | B21: =SUM(B4:B20) -> 3977882 | D21: =SUM(D4:D20) -> 2150888 | G21: 2036423 | H21: =SUM(H4:H20) -> 3681 | I21: =SUM(I4:I20) -> 3597 | J21: =SUM(J4:J20) -> 1496070 | K21: =SUM(K4:K20) -> 3388 | L21: =SUM(L4:L20) -> 330924 | M21: =SUM(M4:M20) -> 209 | N21: =SUM(N4:N20) -> 0 | R21: =SUM(R4:R20) -> 0
D24: Blended | I24: Unit Economics | J24: 1 | K24: 1174
A25: Total Revenue | B25: =B21 -> 3977882 | D25: COGS | E25: =B27/K21 -> 441.5791 | I25: COGS | J25: 0.37 | K25: =K24*37% -> 434.38
A26: Total Units Sold | B26: =K21 -> 3388 | G26: =B27/B25*100 -> 37.609713 | I26: Logitics & Packing | J26: 0.09 | K26: =K24*J26 -> 105.66
A27: COGS | B27: =J21 -> 1496070 | D27: CAC | E27: =B29/K21 -> 601.06936 | G27: =B28/B25*100 -> 8.3191005 | I27: Marketing | J27: 0.51 | K27: =K24*J27 -> 598.74
A28: Logistics | B28: =L21 -> 330924 | D28: Logistics | E28: 92 | G28: =B29/B25*100 -> 51.19365 | I28: Profit | J28: 0.03 | K28: 38
A29: Marketing | B29: =G21 -> 2036423 | D29: AOV | E29: =B25/K21 -> 1174.1092
A30: P&L | B30: =B25-(B27+B28+B29) -> 114465
A31: P&L % | B31: 0.03
A34: May | B34: Amazon
B36: Total revenue | C36: Total expense | D36: Total P/L | E36: Profit % | F36: P/pcs | G36: Total orders | H36: Product expense | I36: Delivered | J36: Return | K36: Amazon expense | L36: RTO% | M36: Only Ad spend | N36: Return GMV
A37: V1 | B37: =737727+35043.52+16470.88 -> 789241.4 | C37: =K37+H37 -> 488123.7 | D37: =B37-C37 -> 301117.7 | E37: =D37/B37*100 -> 38.152801 | F37: =D37/I37 -> 371.29186 | G37: =823+29+8 -> 860 | H37: =250*I37 -> 202750 | I37: =776+27+8 -> 811 | J37: =G37-I37 -> 49 | K37: =16164.28+266484.18 +2725.24 -> 285373.7 | L37: =J37/G37*100 -> 5.6976744 | M37: =152094.75 +28728.79+ 1254.68 -> 182078.22 | N37: =J37*999 -> 48951
A38: V2 | B38: =66559.67+475798+2898 -> 545255.67 | C38: =K38+H38 -> 287411.48 | D38: =B38-C38 -> 257844.19 | E38: =D38/B38*100 -> 47.288677 | F38: =D38/I38 -> 538.29685 | G38: =467+52 -> 519 | H38: =350*I38 -> 167650 | I38: =430+47+2 -> 479 | J38: =G38-I38 -> 40 | K38: =23980.81+95224.67 +556 -> 119761.48 | L38: =J38/G38*100 -> 7.7071291 | M38: =11950.9 + 125741.64 + 13734 -> 151426.54 | N38: =J38*1119 -> 44760
A39: V3 | B39: =5097 -> 5097 | C39: =K39+H39 -> 3514.17 | D39: =B39-C39 -> 1582.83 | E39: =D39/B39*100 -> 31.05415 | F39: =D39/I39 -> 527.61 | G39: 3 | H39: =900*I39 -> 2700 | I39: 3 | J39: =G39-I39 -> 0 | K39: =814.17 -> 814.17 | L39: =J39/G39*100 -> 0 | M39: 0 | N39: =J39*1799 -> 0
A40: V4 | B40: =418231+10374.16+4992.32+5202.65 -> 438800.13 | C40: =K40+H40 -> 408206.65 | D40: =B40-C40 -> 30593.48 | E40: =D40/B40*100 -> 6.9720763 | F40: =D40/I40 -> 31.313695 | G40: =997+18+4+5 -> 1024 | H40: =220*I40 -> 214940 | I40: =938+17+12+10 -> 977 | J40: =G40-I40+5+8 -> 60 | K40: =190465.26+2801.39 -> 193266.65 | L40: =J40/G40*100 -> 5.859375 | M40: =115847.24 + 3622.79 -> 119470.03 | N40: =J40*499 -> 29940
A41: V5 | B41: 0 | C41: =K41+H41 -> 0 | D41: =B41-C41 -> 0 | E41: =D41/B41*100 -> #DIV/0! | F41: =D41/I41 -> #DIV/0! | G41: 0 | H41: =250*I41 -> 0 | I41: 0 | J41: =G41-I41 -> 0 | K41: 0 | L41: =J41/G41*100 -> #DIV/0! | M41: 0 | N41: =J41*1049 -> 0
A42: V6 | B42: =123107+66353.24 -> 189460.24 | C42: =K42+H42 -> 117888.72 | D42: =B42-C42 -> 71571.52 | E42: =D42/B42*100 -> 37.776538 | F42: =D42/I42 -> 455.86955 | G42: =111+60 -> 171 | H42: =320*I42 -> 50240 | I42: =102+55 -> 157 | J42: =G42-I42 -> 14 | K42: =22505.49 +45143.23 -> 67648.72 | L42: =J42/G42*100 -> 8.1871345 | M42: =32897.63 + 475.39 -> 33373.02 | N42: =J42*1249 -> 17486
A43: V7 | B43: =31719.47+36030 -> 67749.47 | C43: =K43+H43 -> 65516.4 | D43: =B43-C43 -> 2233.07 | E43: =D43/B43*100 -> 3.2960701 | F43: =D43/I43 -> 44.6614 | G43: =33+20 -> 53 | H43: =500*I43 -> 25000 | I43: 50 | J43: =G43-I43 -> 3 | K43: =14422.44+26093.96 -> 40516.4 | L43: =J43/G43*100 -> 5.6603774 | M43: =26375.73 + 437.34 -> 26813.07 | N43: =J43*1349 -> 4047
A44: V8 | B44: 0 | C44: =K44+H44 -> 0 | D44: =B44-C44 -> 0 | E44: =D44/B44*100 -> #DIV/0! | F44: =D44/I44 -> #DIV/0! | G44: 0 | H44: =800*I44 -> 0 | I44: 0 | J44: =G44-I44 -> 0 | K44: 0 | L44: =J44/G44*100 -> #DIV/0! | M44: 0 | N44: =J44*1899 -> 0
A45: V9 | B45: =132466+128639.12 -> 261105.12 | C45: =K45+H45 -> 196591.55 | D45: =B45-C45 -> 64513.57 | E45: =D45/B45*100 -> 24.707892 | F45: =D45/I45 -> 504.01227 | G45: =81+75 -> 156 | H45: =1000*I45 -> 128000 | I45: =71+57 -> 128 | J45: =G45-I45 -> 28 | K45: =43949.27+24642.28 -> 68591.55 | L45: =J45/G45*100 -> 17.948718 | M45: =18296.03 + 62.04 -> 18358.07 | N45: =J45*1999 -> 55972
A46: BB | B46: =28535 -> 28535 | C46: =K46+H46 -> 23126.43 | D46: =B46-C46 -> 5408.57 | E46: =D46/B46*100 -> 18.954162 | F46: =D46/I46 -> 104.01096 | G46: 55 | H46: =200*I46 -> 10400 | I46: 52 | J46: =G46-I46 -> 3 | K46: =12726.43 -> 12726.43 | L46: =J46/G46*100 -> 5.4545455 | M46: =10121.88 -> 10121.88 | N46: =J46*599 -> 1797
...

Sheet June 25
A1: June | B1: Shopify
A3: Products | B3: Total Dilivered Revenue | C3: Total expense | D3: Total P/L | E3: Profit % | F3: P/pcs | G3: Ad spent | H3: Total orders | I3: Shipped | J3: Total COGS | K3: Delivered | L3: Shipping charges | M3: RTO | N3: In-transit | O3: RTO% | P3: Shipped% | Q3: Delivered % | R3: CPD | S3: Cancellation % | T3: COGS/Unit
A4: V1 | B4: 632837.04 | C4: =G4+J4+L4 -> 343480 | D4: =B4-C4 -> 289357.04 | E4: =D4/B4*100 -> 45.723784 | F4: =D4/K4 -> 263.29121 | H4: 1136 | I4: 1130 | J4: =K4*T4 -> 241780 | K4: 1099 | L4: =I4*90 -> 101700 | M4: =I4-K4-N4 -> 31 | O4: =M4/I4*100 -> 2.7433628 | P4: =I4/H4*100 -> 99.471831 | Q4: =K4/I4*100 -> 97.256637 | R4: =G4/K4 -> 0 | S4: =100-P4 -> 0.52816901 | T4: 220 | W4: Products
A5: V1- P of 2 | B5: 23546.69 | C5: =G5+J5+L5 -> 8480 | D5: =B5-C5 -> 15066.69 | E5: =D5/B5*100 -> 63.986446 | F5: =D5/K5 -> 941.66813 | H5: 16 | I5: 16 | J5: =K5*T5 -> 7040 | K5: 16 | L5: =I5*90 -> 1440 | M5: =I5-K5-N5 -> 0 | O5: =M5/I5*100 -> 0 | P5: =I5/H5*100 -> 100 | Q5: =K5/I5*100 -> 100 | R5: =G5/K5 -> 0 | S5: =100-P5 -> 0 | T5: 440 | W5: V1
A6: V2 | B6: 348400.03 | C6: =G6+J6+L6 -> 119966 | D6: =B6-C6 -> 228434.03 | E6: =D6/B6*100 -> 65.566593 | F6: =D6/K6 -> 763.99341 | H6: 328 | I6: 323 | J6: =K6*T6 -> 90896 | K6: 299 | L6: =I6*90 -> 29070 | M6: =I6-K6-N6 -> 24 | O6: =M6/I6*100 -> 7.4303406 | P6: =I6/H6*100 -> 98.47561 | Q6: =K6/I6*100 -> 92.569659 | R6: =G6/K6 -> 0 | S6: =100-P6 -> 1.5243902 | T6: 304 | W6: V2
A7: V2- P of 2 | B7: 8965.27 | C7: =G7+J7+L7 -> 2792 | D7: =B7-C7 -> 6173.27 | E7: =D7/B7*100 -> 68.857603 | F7: =D7/K7 -> 1543.3175 | H7: 5 | I7: 4 | J7: =K7*T7 -> 2432 | K7: 4 | L7: =I7*90 -> 360 | M7: =I7-K7-N7 -> 0 | O7: =M7/I7*100 -> 0 | P7: =I7/H7*100 -> 80 | Q7: =K7/I7*100 -> 100 | R7: =G7/K7 -> 0 | S7: =100-P7 -> 20 | T7: 608 | W7: V3
A8: V3 | B8: 540771.57 | C8: =G8+J8+L8 -> 297484 | D8: =B8-C8 -> 243287.57 | E8: =D8/B8*100 -> 44.988972 | F8: =D8/K8 -> 620.63156 | H8: 441 | I8: 422 | J8: =K8*T8 -> 259504 | K8: 392 | L8: =I8*90 -> 37980 | M8: =I8-K8-N8 -> 30 | O8: =M8/I8*100 -> 7.1090047 | P8: =I8/H8*100 -> 95.69161 | Q8: =K8/I8*100 -> 92.890995 | R8: =G8/K8 -> 0 | S8: =100-P8 -> 4.30839 | T8: 662 | W8: V4
A9: V4 | B9: 63290.51 | C9: =G9+J9+L9 -> 32504 | D9: =B9-C9 -> 30786.51 | E9: =D9/B9*100 -> 48.643169 | F9: =D9/K9 -> 265.40095 | H9: 126 | I9: 124 | J9: =K9*T9 -> 21344 | K9: 116 | L9: =I9*90 -> 11160 | M9: =I9-K9-N9 -> 8 | O9: =M9/I9*100 -> 6.4516129 | P9: =I9/H9*100 -> 98.412698 | Q9: =K9/I9*100 -> 93.548387 | R9: =G9/K9 -> 0 | S9: =100-P9 -> 1.5873016 | T9: 184 | W9: V5
A10: V4- P of 2 | B10: 29336.01 | C10: =G10+J10+L10 -> 14746 | D10: =B10-C10 -> 14590.01 | E10: =D10/B10*100 -> 49.734132 | F10: =D10/K10 -> 455.93781 | H10: 35 | I10: 33 | J10: =K10*T10 -> 11776 | K10: 32 | L10: =I10*90 -> 2970 | M10: =I10-K10-N10 -> 1 | O10: =M10/I10*100 -> 3.030303 | P10: =I10/H10*100 -> 94.285714 | Q10: =K10/I10*100 -> 96.969697 | R10: =G10/K10 -> 0 | S10: =100-P10 -> 5.7142857 | T10: 368 | W10: V6
A11: V5 | B11: 0 | C11: =G11+J11+L11 -> 0 | D11: =B11-C11 -> 0 | E11: =D11/B11*100 -> #DIV/0! | F11: =D11/K11 -> #DIV/0! | H11: 0 | I11: 0 | J11: =K11*T11 -> 0 | K11: 0 | L11: =I11*90 -> 0 | M11: =I11-K11-N11 -> 0 | T11: 206 | W11: V7
A12: V6 | B12: 167997.29 | C12: =G12+J12+L12 -> 57994 | D12: =B12-C12 -> 110003.29 | E12: =D12/B12*100 -> 65.479205 | F12: =D12/K12 -> 769.25378 | H12: 158 | I12: 155 | J12: =K12*T12 -> 44044 | K12: 143 | L12: =I12*90 -> 13950 | M12: =I12-K12-N12 -> 11 | N12: 1 | O12: =M12/I12*100 -> 7.0967742 | P12: =I12/H12*100 -> 98.101266 | Q12: =K12/I12*100 -> 92.258065 | R12: =G12/K12 -> 0 | S12: =100-P12 -> 1.8987342 | T12: 308 | W12: V8
A13: V6- P of 2 | B13: 8766.1 | C13: =G13+J13+L13 -> 2914 | D13: =B13-C13 -> 5852.1 | E13: =D13/B13*100 -> 66.758308 | F13: =D13/K13 -> 1463.025 | H13: 5 | I13: 5 | J13: =K13*T13 -> 2464 | K13: 4 | L13: =I13*90 -> 450 | M13: =I13-K13-N13 -> 1 | O13: =M13/I13*100 -> 20 | P13: =I13/H13*100 -> 100 | Q13: =K13/I13*100 -> 80 | R13: =G13/K13 -> 0 | S13: =100-P13 -> 0 | T13: 616 | W13: V9
A14: V7 | B14: 78617.16 | C14: =G14+J14+L14 -> 40515 | D14: =B14-C14 -> 38102.16 | E14: =D14/B14*100 -> 48.46545 | F14: =D14/K14 -> 494.83325 | H14: 82 | I14: 78 | J14: =K14*T14 -> 33495 | K14: 77 | L14: =I14*90 -> 7020 | M14: =I14-K14-N14 -> 1 | O14: =M14/I14*100 -> 1.2820513 | P14: =I14/H14*100 -> 95.121951 | Q14: =K14/I14*100 -> 98.717949 | R14: =G14/K14 -> 0 | S14: =100-P14 -> 4.8780488 | T14: 435 | W14: V10
A15: V8 | B15: 0 | C15: =G15+J15+L15 -> 0 | D15: =B15-C15 -> 0 | E15: =D15/B15*100 -> #DIV/0! | F15: =D15/K15 -> #DIV/0! | H15: 0 | I15: 0 | J15: =K15*T15 -> 0 | K15: 0 | L15: =I15*90 -> 0 | M15: =I15-K15-N15 -> 0 | T15: 699
A16: V9 | B16: 1333289.1 | C16: =G16+J16+L16 -> 634218 | D16: =B16-C16 -> 699071.05 | E16: =D16/B16*100 -> 52.43207 | F16: =D16/K16 -> 962.90778 | H16: 788 | I16: 771 | J16: =K16*T16 -> 564828 | K16: 726 | L16: =I16*90 -> 69390 | M16: =I16-K16-N16 -> 45 | O16: =M16/I16*100 -> 5.8365759 | P16: =I16/H16*100 -> 97.84264 | Q16: =K16/I16*100 -> 94.163424 | R16: =G16/K16 -> 0 | S16: =100-P16 -> 2.1573604 | T16: 778
A17: V9 P of 2 | B17: 31338.48 | C17: =G17+J17+L17 -> 16460 | D17: =B17-C17 -> 14878.48 | E17: =D17/B17*100 -> 47.476712 | F17: =D17/K17 -> 1487.848 | H17: 12 | I17: 10 | J17: =K17*T17 -> 15560 | K17: 10 | L17: =I17*90 -> 900 | M17: =I17-K17-N17 -> 0 | O17: =M17/I17*100 -> 0 | P17: =I17/H17*100 -> 83.333333 | Q17: =K17/I17*100 -> 100 | R17: =G17/K17 -> 0 | S17: =100-P17 -> 16.666667 | T17: 1556
A18: V10 | B18: 589604.84 | C18: =G18+J18+L18 -> 364541 | D18: =B18-C18 -> 225063.84 | E18: =D18/B18*100 -> 38.17198 | F18: =D18/K18 -> 684.08462 | H18: 389 | I18: 362 | J18: =K18*T18 -> 331961 | K18: 329 | L18: =I18*90 -> 32580 | M18: =I18-K18-N18 -> 32 | N18: 1 | O18: =M18/I18*100 -> 8.839779 | P18: =I18/H18*100 -> 93.059126 | Q18: =K18/I18*100 -> 90.883978 | R18: =G18/K18 -> 0 | S18: =100-P18 -> 6.940874 | T18: 1009
A19: Busy Book | B19: 73782.27 | C19: =G19+J19+L19 -> 57480 | D19: =B19-C19 -> 16302.27 | E19: =D19/B19*100 -> 22.095105 | F19: =D19/K19 -> 97.037321 | H19: 186 | I19: 172 | J19: =K19*T19 -> 42000 | K19: 168 | L19: =I19*90 -> 15480 | M19: =I19-K19-N19 -> 4 | O19: =M19/I19*100 -> 2.3255814 | P19: =I19/H19*100 -> 92.473118 | Q19: =K19/I19*100 -> 97.674419 | R19: =G19/K19 -> 0 | S19: =100-P19 -> 7.5268817 | T19: 250
A20: Busy Book Pink | B20: 58295.38 | C20: =G20+J20+L20 -> 25740 | D20: =B20-C20 -> 32555.38 | E20: =D20/B20*100 -> 55.845558 | F20: =D20/K20 -> 493.26333 | H20: 111 | I20: 66 | J20: =K20*T20 -> 19800 | K20: 66 | L20: =I20*90 -> 5940 | M20: =I20-K20-N20 -> 0 | O20: =M20/I20*100 -> 0 | P20: =I20/H20*100 -> 59.459459 | Q20: =K20/I20*100 -> 100 | R20: =G20/K20 -> 0 | S20: =100-P20 -> 40.540541 | T20: 300
A21: Human Book | B21: 44191.69 | C21: =G21+J21+L21 -> 23880 | D21: =B21-C21 -> 20311.69 | E21: =D21/B21*100 -> 45.962691 | F21: =D21/K21 -> 332.97852 | H21: 72 | I21: 62 | J21: =K21*T21 -> 18300 | K21: 61 | L21: =I21*90 -> 5580 | M21: =I21-K21-N21 -> 0 | N21: 1 | O21: =M21/I21*100 -> 0 | P21: =I21/H21*100 -> 86.111111 | Q21: =K21/I21*100 -> 98.387097 | R21: =G21/K21 -> 0 | S21: =100-P21 -> 13.888889 | T21: 300
A22: V9-V3 Combo | B22: 215784.73 | C22: =G22+J22+L22 -> 127260 | D22: =B22-C22 -> 88524.73 | E22: =D22/B22*100 -> 41.024557 | F22: =D22/K22 -> 1066.563 | H22: 89 | I22: 86 | J22: =K22*T22 -> 119520 | K22: 83 | L22: =I22*90 -> 7740 | M22: =I22-K22-N22 -> 3 | O22: =M22/I22*100 -> 3.4883721 | P22: =I22/H22*100 -> 96.629213 | Q22: =K22/I22*100 -> 96.511628 | R22: =G22/K22 -> 0 | S22: =100-P22 -> 3.3707865 | T22: 1440
A23: V9-V10 Combo | B23: 112465.89 | C23: =G23+J23+L23 -> 80891 | D23: =B23-C23 -> 31574.89 | E23: =D23/B23*100 -> 28.075081 | F23: =D23/K23 -> 734.29977 | H23: 46 | I23: 45 | J23: =K23*T23 -> 76841 | K23: 43 | L23: =I23*90 -> 4050 | M23: =I23-K23-N23 -> 2 | O23: =M23/I23*100 -> 4.4444444 | P23: =I23/H23*100 -> 97.826087 | Q23: =K23/I23*100 -> 95.555556 | R23: =G23/K23 -> 0 | S23: =100-P23 -> 2.173913 | T23: 1787
A24: V7-V4 Combo | B24: 13958.41 | C24: =G24+J24+L24 -> 5852 | D24: =B24-C24 -> 8106.41 | E24: =D24/B24*100 -> 58.075454 | F24: =D24/K24 -> 1013.3012 | H24: 12 | I24: 10 | J24: =K24*T24 -> 4952 | K24: 8 | L24: =I24*90 -> 900 | M24: =I24-K24-N24 -> 2 | O24: =M24/I24*100 -> 20 | P24: =I24/H24*100 -> 83.333333 | Q24: =K24/I24*100 -> 80 | R24: =G24/K24 -> 0 | S24: =100-P24 -> 16.666667 | T24: 619
A25: V1-V4 Combo | B25: 76710.99 | C25: =G25+J25+L25 -> 31976 | D25: =B25-C25 -> 44734.99 | E25: =D25/B25*100 -> 58.316273 | F25: =D25/K25 -> 698.98422 | H25: 68 | I25: 68 | J25: =K25*T25 -> 25856 | K25: 64 | L25: =I25*90 -> 6120 | M25: =I25-K25-N25 -> 4 | O25: =M25/I25*100 -> 5.8823529 | P25: =I25/H25*100 -> 100 | Q25: =K25/I25*100 -> 94.117647 | R25: =G25/K25 -> 0 | S25: =100-P25 -> 0 | T25: 404
A26: V1-V7 Combo | B26: 33500.28 | C26: =G26+J26+L26 -> 14245 | D26: =B26-C26 -> 19255.28 | E26: =D26/B26*100 -> 57.477967 | F26: =D26/K26 -> 1013.4358 | H26: 20 | I26: 20 | J26: =K26*T26 -> 12445 | K26: 19 | L26: =I26*90 -> 1800 | M26: =I26-K26-N26 -> 1 | O26: =M26/I26*100 -> 5 | P26: =I26/H26*100 -> 100 | Q26: =K26/I26*100 -> 95 | R26: =G26/K26 -> 0 | S26: =100-P26 -> 0 | T26: 655
A27: V6-V2 Combo | B27: 42657.4 | C27: =G27+J27+L27 -> 14922 | D27: =B27-C27 -> 27735.4 | E27: =D27/B27*100 -> 65.018965 | F27: =D27/K27 -> 1320.7333 | H27: 26 | I27: 23 | J27: =K27*T27 -> 12852 | K27: 21 | L27: =I27*90 -> 2070 | M27: =I27-K27-N27 -> 2 | O27: =M27/I27*100 -> 8.6956522 | P27: =I27/H27*100 -> 88.461538 | Q27: =K27/I27*100 -> 91.304348 | R27: =G27/K27 -> 0 | S27: =100-P27 -> 11.538462 | T27: 612
A28: V6-V7 Combo | B28: 38376.76 | C28: =G28+J28+L28 -> 17493 | D28: =B28-C28 -> 20883.76 | E28: =D28/B28*100 -> 54.417726 | F28: =D28/K28 -> 994.46476 | H28: 21 | I28: 21 | J28: =K28*T28 -> 15603 | K28: 21 | L28: =I28*90 -> 1890 | M28: =I28-K28-N28 -> 0 | O28: =M28/I28*100 -> 0 | P28: =I28/H28*100 -> 100 | Q28: =K28/I28*100 -> 100 | R28: =G28/K28 -> 0 | S28: =100-P28 -> 0 | T28: 743
A29: V2-V7 Combo | B29: 35758.4 | C29: =G29+J29+L29 -> 17409 | D29: =B29-C29 -> 18349.4 | E29: =D29/B29*100 -> 51.314936 | F29: =D29/K29 -> 873.78095 | H29: 21 | I29: 21 | J29: =K29*T29 -> 15519 | K29: 21 | L29: =I29*90 -> 1890 | M29: =I29-K29-N29 -> 0 | O29: =M29/I29*100 -> 0 | P29: =I29/H29*100 -> 100 | Q29: =K29/I29*100 -> 100 | R29: =G29/K29 -> 0 | S29: =100-P29 -> 0 | T29: 739
A30: V1-V2 Combo | B30: 25700.81 | C30: =G30+J30+L30 -> 8866 | D30: =B30-C30 -> 16834.81 | E30: =D30/B30*100 -> 65.503033 | F30: =D30/K30 -> 1202.4864 | H30: 18 | I30: 17 | J30: =K30*T30 -> 7336 | K30: 14 | L30: =I30*90 -> 1530 | M30: =I30-K30-N30 -> 2 | N30: 1 | O30: =M30/I30*100 -> 11.764706 | P30: =I30/H30*100 -> 94.444444 | Q30: =K30/I30*100 -> 82.352941 | R30: =G30/K30 -> 0 | S30: =100-P30 -> 5.5555556 | T30: 524
A31: V6-V4 Combo | B31: 14372.6 | C31: =G31+J31+L31 -> 4746 | D31: =B31-C31 -> 9626.6 | E31: =D31/B31*100 -> 66.978835 | F31: =D31/K31 -> 1203.325 | H31: 9 | I31: 9 | J31: =K31*T31 -> 3936 | K31: 8 | L31: =I31*90 -> 810 | M31: =I31-K31-N31 -> 1 | O31: =M31/I31*100 -> 11.111111 | P31: =I31/H31*100 -> 100 | Q31: =K31/I31*100 -> 88.888889 | R31: =G31/K31 -> 0 | S31: =100-P31 -> 0 | T31: 492
A32: V2-V4 Combo | B32: 9084.1 | C32: =G32+J32+L32 -> 3468 | D32: =B32-C32 -> 5616.1 | E32: =D32/B32*100 -> 61.823406 | F32: =D32/K32 -> 936.01667 | H32: 7 | I32: 6 | J32: =K32*T32 -> 2928 | K32: 6 | L32: =I32*90 -> 540 | M32: =I32-K32-N32 -> 0 | O32: =M32/I32*100 -> 0 | P32: =I32/H32*100 -> 85.714286 | Q32: =K32/I32*100 -> 100 | R32: =G32/K32 -> 0 | S32: =100-P32 -> 14.285714 | T32: 488
A33: Total | B33: 4707817 | D33: =SUM(D4:D32) -> 2281077.8 | G33: 2001000 | H33: =SUM(H4:H32) -> 4227 | I33: =SUM(I4:I32) -> 4059 | J33: =SUM(J4:J32) -> 2005012 | K33: =SUM(K4:K32) -> 3850 | L33: =SUM(L4:L32) -> 365310 | M33: =SUM(M4:M32) -> 205 | N33: =SUM(N4:N32) -> 4 | O33: =AVERAGE(O4:O32) -> 5.2789639 | P33: =AVERAGE(P4:P32) -> 93.268458 | Q33: =AVERAGE(Q4:Q32) -> 94.409308 | R33: =SUM(R4:R32) -> 0 | S33: =AVERAGE(S4:S32) -> 6.7315418
D36: Blended
A37: Total Units Sold | B37: =K33 -> 3850
A38: Total Revenue | B38: =B33 -> 4707817 | D38: COGS | E38: =B39/B37 -> 520.78234
A39: COGS | B39: =J33 -> 2005012 | D39: CAC | E39: 674
A40: Logistics | B40: =L33 -> 365310 | D40: Logistics | E40: =B40/B37 -> 94.885714
A41: Marketing | B41: =G33 -> 2001000 | D41: AOV | E41: =B38/B37 -> 1222.8096
A42: P&L | B42: =B38-(B39+B40+B41) -> 336495
A43: P&L % | B43: =B42/B38 -> 0.071475803
...

Sheet July 25
A1: July | B1: Shopify
A3: Products | B3: Total Dilivered Revenue | C3: Total expense | D3: Total P/L | E3: Profit % | F3: P/pcs | G3: Ad spent | H3: Total orders | I3: Shipped | J3: Total COGS | K3: Delivered | L3: Shipping charges | M3: RTO | N3: In-transit | O3: RTO% | P3: Shipped% | Q3: Delivered % | R3: CPD | S3: Cancellation % | T3: COGS/Unit
A4: V1 | B4: 974085.05 | C4: =G4+J4+L4 -> 530084 | D4: =B4-C4 -> 444001.05 | E4: =D4/B4*100 -> 45.581343 | F4: =D4/K4 -> 264.44375 | H4: 1739 | I4: 1728 | J4: =K4*T4 -> 369380 | K4: 1679 | L4: =I4*93 -> 160704 | M4: =I4-K4-N4 -> 44 | N4: 5 | O4: =M4/I4*100 -> 2.5462963 | P4: =I4/H4*100 -> 99.367453 | Q4: =K4/I4*100 -> 97.164352 | R4: =G4/K4 -> 0 | S4: =100-P4 -> 0.63254744 | T4: 220 | W4: Products | X4: Total Cost
A5: V1- P of 2 | B5: 72563.57 | C5: =G5+J5+L5 -> 27462 | D5: =B5-C5 -> 45101.57 | E5: =D5/B5*100 -> 62.154563 | F5: =D5/K5 -> 884.34451 | H5: 54 | I5: 54 | J5: =K5*T5 -> 22440 | K5: 51 | L5: =I5*93 -> 5022 | M5: =I5-K5-N5 -> 3 | O5: =M5/I5*100 -> 5.5555556 | P5: =I5/H5*100 -> 100 | Q5: =K5/I5*100 -> 94.444444 | R5: =G5/K5 -> 0 | T5: 440 | W5: V1 | X5: 220
A6: V2 | B6: 1021573.8 | C6: =G6+J6+L6 -> 360620 | D6: =B6-C6 -> 660953.81 | E6: =D6/B6*100 -> 64.699565 | F6: =D6/K6 -> 747.68531 | H6: 996 | I6: 988 | J6: =K6*T6 -> 268736 | K6: 884 | L6: =I6*93 -> 91884 | M6: =I6-K6-N6 -> 96 | N6: 8 | O6: =M6/I6*100 -> 9.7165992 | P6: =I6/H6*100 -> 99.196787 | Q6: =K6/I6*100 -> 89.473684 | R6: =G6/K6 -> 0 | S6: =100-P6 -> 0.80321285 | T6: 304 | W6: V2 | X6: 304
A7: V2- P of 2 | B7: 62226.26 | C7: =G7+J7+L7 -> 20422 | D7: =B7-C7 -> 41804.26 | E7: =D7/B7*100 -> 67.181058 | F7: =D7/K7 -> 1441.5262 | H7: 30 | I7: 30 | J7: =K7*T7 -> 17632 | K7: 29 | L7: =I7*93 -> 2790 | M7: =I7-K7-N7 -> 1 | O7: =M7/I7*100 -> 3.3333333 | P7: =I7/H7*100 -> 100 | Q7: =K7/I7*100 -> 96.666667 | R7: =G7/K7 -> 0 | T7: 608 | W7: V3 | X7: 662
A8: V3 | B8: 335622.39 | C8: =G8+J8+L8 -> 186846 | D8: =B8-C8 -> 148776.39 | E8: =D8/B8*100 -> 44.328506 | F8: =D8/K8 -> 604.78207 | H8: 265 | I8: 258 | J8: =K8*T8 -> 162852 | K8: 246 | L8: =I8*93 -> 23994 | M8: =I8-K8-N8 -> 12 | O8: =M8/I8*100 -> 4.6511628 | P8: =I8/H8*100 -> 97.358491 | Q8: =K8/I8*100 -> 95.348837 | R8: =G8/K8 -> 0 | S8: =100-P8 -> 2.6415094 | T8: 662 | W8: V4 | X8: 184
A9: V4 | B9: 59048.48 | C9: =G9+J9+L9 -> 31214 | D9: =B9-C9 -> 27834.48 | E9: =D9/B9*100 -> 47.138351 | F9: =D9/K9 -> 253.04073 | H9: 124 | I9: 118 | J9: =K9*T9 -> 20240 | K9: 110 | L9: =I9*93 -> 10974 | M9: =I9-K9-N9 -> 7 | N9: 1 | O9: =M9/I9*100 -> 5.9322034 | P9: =I9/H9*100 -> 95.16129 | Q9: =K9/I9*100 -> 93.220339 | R9: =G9/K9 -> 0 | S9: =100-P9 -> 4.8387097 | T9: 184 | W9: V5 | X9: 206
A10: V4- P of 2 | B10: 10547.63 | C10: =G10+J10+L10 -> 5625 | D10: =B10-C10 -> 4922.63 | E10: =D10/B10*100 -> 46.670484 | F10: =D10/K10 -> 410.21917 | H10: 13 | I10: 13 | J10: =K10*T10 -> 4416 | K10: 12 | L10: =I10*93 -> 1209 | M10: =I10-K10-N10 -> 1 | O10: =M10/I10*100 -> 7.6923077 | P10: =I10/H10*100 -> 100 | Q10: =K10/I10*100 -> 92.307692 | R10: =G10/K10 -> 0 | T10: 368 | W10: V6 | X10: 308
A11: V5 | B11: 0 | C11: 0 | D11: 0 | E11: =D11/B11*100 -> #DIV/0! | F11: 0 | H11: 0 | I11: 0 | J11: 0 | K11: 0 | L11: =I11*93 -> 0 | M11: =I11-K11-N11 -> 0 | T11: 206 | W11: V7 | X11: 435
A12: V6 | B12: 773994.26 | C12: =G12+J12+L12 -> 275750 | D12: =B12-C12 -> 498244.26 | E12: =D12/B12*100 -> 64.373121 | F12: =D12/K12 -> 750.36786 | H12: 772 | I12: 766 | J12: =K12*T12 -> 204512 | K12: 664 | L12: =I12*93 -> 71238 | M12: =I12-K12-N12 -> 91 | N12: 11 | O12: =M12/I12*100 -> 11.879896 | P12: =I12/H12*100 -> 99.222798 | Q12: =K12/I12*100 -> 86.684073 | R12: =G12/K12 -> 0 | S12: =100-P12 -> 0.77720207 | T12: 308 | W12: V8 | X12: 699
A13: V6- P of 2 | B13: 29553.9 | C13: =G13+J13+L13 -> 10019 | D13: =B13-C13 -> 19534.9 | E13: =D13/B13*100 -> 66.099229 | F13: =D13/K13 -> 1395.35 | H13: 16 | I13: 15 | J13: =K13*T13 -> 8624 | K13: 14 | L13: =I13*93 -> 1395 | M13: =I13-K13-N13 -> 1 | O13: =M13/I13*100 -> 6.6666667 | P13: =I13/H13*100 -> 93.75 | Q13: =K13/I13*100 -> 93.333333 | R13: =G13/K13 -> 0 | S13: =100-P13 -> 6.25 | T13: 616 | W13: V9 | X13: 778
A14: V7 | B14: 83132.63 | C14: =G14+J14+L14 -> 46029 | D14: =B14-C14 -> 37103.63 | E14: =D14/B14*100 -> 44.631849 | F14: =D14/K14 -> 426.47851 | H14: 89 | I14: 88 | J14: =K14*T14 -> 37845 | K14: 87 | L14: =I14*93 -> 8184 | M14: =I14-K14-N14 -> 1 | O14: =M14/I14*100 -> 1.1363636 | P14: =I14/H14*100 -> 98.876404 | Q14: =K14/I14*100 -> 98.863636 | R14: =G14/K14 -> 0 | S14: =100-P14 -> 1.1235955 | T14: 435 | W14: V10 | X14: 1009
A15: V8 | B15: 0 | C15: 0 | D15: 0 | E15: =D15/B15*100 -> #DIV/0! | F15: 0 | H15: 0 | I15: 0 | J15: 0 | K15: 0 | L15: =I15*93 -> 0 | M15: =I15-K15-N15 -> 0 | T15: 699
A16: V9 | B16: 1072812.1 | C16: =G16+J16+L16 -> 548095 | D16: =B16-C16 -> 524717.12 | E16: =D16/B16*100 -> 48.910439 | F16: =D16/K16 -> 839.54739 | H16: 670 | I16: 665 | J16: =K16*T16 -> 486250 | K16: 625 | L16: =I16*93 -> 61845 | M16: =I16-K16-N16 -> 39 | N16: 1 | O16: =M16/I16*100 -> 5.8646617 | P16: =I16/H16*100 -> 99.253731 | Q16: =K16/I16*100 -> 93.984962 | R16: =G16/K16 -> 0 | S16: =100-P16 -> 0.74626866 | T16: 778
A17: V9 P of 2 | B17: 33662.44 | C17: =G17+J17+L17 -> 19974 | D17: =B17-C17 -> 13688.44 | E17: =D17/B17*100 -> 40.663838 | F17: =D17/K17 -> 1140.7033 | H17: 14 | I17: 14 | J17: =K17*T17 -> 18672 | K17: 12 | L17: =I17*93 -> 1302 | M17: =I17-K17-N17 -> 2 | O17: =M17/I17*100 -> 14.285714 | P17: =I17/H17*100 -> 100 | Q17: =K17/I17*100 -> 85.714286 | R17: =G17/K17 -> 0 | T17: 1556
A18: V10 | B18: 98679.54 | C18: =G18+J18+L18 -> 63372 | D18: =B18-C18 -> 35307.54 | E18: =D18/B18*100 -> 35.780001 | F18: =D18/K18 -> 619.43053 | H18: 65 | I18: 63 | J18: =K18*T18 -> 57513 | K18: 57 | L18: =I18*93 -> 5859 | M18: =I18-K18-N18 -> 4 | N18: 2 | O18: =M18/I18*100 -> 6.3492063 | P18: =I18/H18*100 -> 96.923077 | Q18: =K18/I18*100 -> 90.47619 | R18: =G18/K18 -> 0 | S18: =100-P18 -> 3.0769231 | T18: 1009
A19: Busy Book | B19: 56466.36 | C19: =G19+J19+L19 -> 43497 | D19: =B19-C19 -> 12969.36 | E19: =D19/B19*100 -> 22.968295 | F19: =D19/K19 -> 102.93143 | H19: 129 | I19: 129 | J19: =K19*T19 -> 31500 | K19: 126 | L19: =I19*93 -> 11997 | M19: =I19-K19-N19 -> 3 | O19: =M19/I19*100 -> 2.3255814 | P19: =I19/H19*100 -> 100 | Q19: =K19/I19*100 -> 97.674419 | R19: =G19/K19 -> 0 | T19: 250
A20: Busy Book Pink | B20: 61001.78 | C20: =G20+J20+L20 -> 28254 | D20: =B20-C20 -> 32747.78 | E20: =D20/B20*100 -> 53.683319 | F20: =D20/K20 -> 467.82543 | H20: 78 | I20: 78 | J20: =K20*T20 -> 21000 | K20: 70 | L20: =I20*93 -> 7254 | M20: =I20-K20-N20 -> 8 | O20: =M20/I20*100 -> 10.25641 | P20: =I20/H20*100 -> 100 | Q20: =K20/I20*100 -> 89.74359 | R20: =G20/K20 -> 0 | T20: 300
A21: Busy Book Blue | B21: 6340.59 | C21: =G21+J21+L21 -> 2844 | D21: =B21-C21 -> 3496.59 | E21: =D21/B21*100 -> 55.14613 | F21: =D21/K21 -> 499.51286 | H21: 8 | I21: 8 | J21: =K21*T21 -> 2100 | K21: 7 | L21: =I21*93 -> 744 | M21: =I21-K21-N21 -> 1 | O21: =M21/I21*100 -> 12.5 | P21: =I21/H21*100 -> 100 | Q21: =K21/I21*100 -> 87.5 | R21: =G21/K21 -> 0 | T21: 300
A22: Human Book | B22: 140649.32 | C22: =G22+J22+L22 -> 78837 | D22: =B22-C22 -> 61812.32 | E22: =D22/B22*100 -> 43.947827 | F22: =D22/K22 -> 312.18343 | H22: 211 | I22: 209 | J22: =K22*T22 -> 59400 | K22: 198 | L22: =I22*93 -> 19437 | M22: =I22-K22-N22 -> 9 | N22: 2 | O22: =M22/I22*100 -> 4.3062201 | P22: =I22/H22*100 -> 99.052133 | Q22: =K22/I22*100 -> 94.736842 | R22: =G22/K22 -> 0 | S22: =100-P22 -> 0.9478673 | T22: 300
A23: V9-V3 Combo | B23: 116723.77 | C23: =G23+J23+L23 -> 61599 | D23: =B23-C23 -> 55124.77 | E23: =D23/B23*100 -> 47.226687 | F23: =D23/K23 -> 1378.1192 | H23: 44 | I23: 43 | J23: =K23*T23 -> 57600 | K23: 40 | L23: =I23*93 -> 3999 | M23: =I23-K23-N23 -> 2 | N23: 1 | O23: =M23/I23*100 -> 4.6511628 | P23: =I23/H23*100 -> 97.727273 | Q23: =K23/I23*100 -> 93.023256 | R23: =G23/K23 -> 0 | S23: =100-P23 -> 2.2727273 | T23: 1440
A24: V9-V10 Combo | B24: 153524.67 | C24: =G24+J24+L24 -> 99733 | D24: =B24-C24 -> 53791.67 | E24: =D24/B24*100 -> 35.037802 | F24: =D24/K24 -> 1014.9372 | H24: 54 | I24: 54 | J24: =K24*T24 -> 94711 | K24: 53 | L24: =I24*93 -> 5022 | M24: =I24-K24-N24 -> 1 | O24: =M24/I24*100 -> 1.8518519 | P24: =I24/H24*100 -> 100 | Q24: =K24/I24*100 -> 98.148148 | R24: =G24/K24 -> 0 | T24: 1787
A25: V7-V4 Combo | B25: 3648 | C25: =G25+J25+L25 -> 1424 | D25: =B25-C25 -> 2224 | E25: =D25/B25*100 -> 60.964912 | F25: =D25/K25 -> 1112 | H25: 2 | I25: 2 | J25: =K25*T25 -> 1238 | K25: 2 | L25: =I25*93 -> 186 | M25: =I25-K25-N25 -> 0 | P25: =I25/H25*100 -> 100 | Q25: =K25/I25*100 -> 100 | R25: =G25/K25 -> 0 | T25: 619
A26: V1-V4 Combo | B26: 78312.62 | C26: =G26+J26+L26 -> 32552 | D26: =B26-C26 -> 45760.62 | E26: =D26/B26*100 -> 58.433264 | F26: =D26/K26 -> 715.00969 | H26: 73 | I26: 72 | J26: =K26*T26 -> 25856 | K26: 64 | L26: =I26*93 -> 6696 | M26: =I26-K26-N26 -> 7 | N26: 1 | O26: =M26/I26*100 -> 9.7222222 | P26: =I26/H26*100 -> 98.630137 | Q26: =K26/I26*100 -> 88.888889 | R26: =G26/K26 -> 0 | S26: =100-P26 -> 1.369863 | T26: 404
A27: V1-V7 Combo | B27: 76267.21 | C27: =G27+J27+L27 -> 33191 | D27: =B27-C27 -> 43076.21 | E27: =D27/B27*100 -> 56.480642 | F27: =D27/K27 -> 979.00477 | H27: 47 | I27: 47 | J27: =K27*T27 -> 28820 | K27: 44 | L27: =I27*93 -> 4371 | M27: =I27-K27-N27 -> 2 | N27: 1 | O27: =M27/I27*100 -> 4.2553191 | P27: =I27/H27*100 -> 100 | Q27: =K27/I27*100 -> 93.617021 | R27: =G27/K27 -> 0 | T27: 655
A28: V6-V2 Combo | B28: 35495.91 | C28: =G28+J28+L28 -> 12690 | D28: =B28-C28 -> 22805.91 | E28: =D28/B28*100 -> 64.249402 | F28: =D28/K28 -> 1266.995 | H28: 19 | I28: 18 | J28: =K28*T28 -> 11016 | K28: 18 | L28: =I28*93 -> 1674 | M28: =I28-K28-N28 -> 0 | P28: =I28/H28*100 -> 94.736842 | Q28: =K28/I28*100 -> 100 | R28: =G28/K28 -> 0 | S28: =100-P28 -> 5.2631579 | T28: 612
A29: V6-V7 Combo | B29: 157668.17 | C29: =G29+J29+L29 -> 74126 | D29: =B29-C29 -> 83542.17 | E29: =D29/B29*100 -> 52.986072 | F29: =D29/K29 -> 949.34284 | H29: 97 | I29: 94 | J29: =K29*T29 -> 65384 | K29: 88 | L29: =I29*93 -> 8742 | M29: =I29-K29-N29 -> 5 | N29: 1 | O29: =M29/I29*100 -> 5.3191489 | P29: =I29/H29*100 -> 96.907216 | Q29: =K29/I29*100 -> 93.617021 | R29: =G29/K29 -> 0 | S29: =100-P29 -> 3.0927835 | T29: 743
A30: V2-V7 Combo | B30: 78961.22 | C30: =G30+J30+L30 -> 35962 | D30: =B30-C30 -> 42999.22 | E30: =D30/B30*100 -> 54.456124 | F30: =D30/K30 -> 999.98186 | H30: 46 | I30: 45 | J30: =K30*T30 -> 31777 | K30: 43 | L30: =I30*93 -> 4185 | M30: =I30-K30-N30 -> 2 | O30: =M30/I30*100 -> 4.4444444 | P30: =I30/H30*100 -> 97.826087 | Q30: =K30/I30*100 -> 95.555556 | R30: =G30/K30 -> 0 | S30: =100-P30 -> 2.173913 | T30: 739
A31: V1-V2 Combo | B31: 46484.13 | C31: =G31+J31+L31 -> 14901 | D31: =B31-C31 -> 31583.13 | E31: =D31/B31*100 -> 67.943898 | F31: =D31/K31 -> 1315.9637 | H31: 25 | I31: 25 | J31: =K31*T31 -> 12576 | K31: 24 | L31: =I31*93 -> 2325 | M31: =I31-K31-N31 -> 1 | O31: =M31/I31*100 -> 4 | P31: =I31/H31*100 -> 100 | Q31: =K31/I31*100 -> 96 | R31: =G31/K31 -> 0 | T31: 524
A32: V6-V4 Combo | B32: 5497 | C32: =G32+J32+L32 -> 1755 | D32: =B32-C32 -> 3742 | E32: =D32/B32*100 -> 68.073495 | F32: =D32/K32 -> 1247.3333 | H32: 3 | I32: 3 | J32: =K32*T32 -> 1476 | K32: 3 | L32: =I32*93 -> 279 | M32: =I32-K32-N32 -> 0 | P32: =I32/H32*100 -> 100 | Q32: =K32/I32*100 -> 100 | R32: =G32/K32 -> 0 | T32: 492
A33: V2-V4 Combo | B33: 21095.32 | C33: =G33+J33+L33 -> 8134 | D33: =B33-C33 -> 12961.32 | E33: =D33/B33*100 -> 61.441685 | F33: =D33/K33 -> 925.80857 | H33: 14 | I33: 14 | J33: =K33*T33 -> 6832 | K33: 14 | L33: =I33*93 -> 1302 | M33: =I33-K33-N33 -> 0 | P33: =I33/H33*100 -> 100 | Q33: =K33/I33*100 -> 100 | R33: =G33/K33 -> 0 | T33: 488
A34: Total | B34: =sum(B4:B33)+80000 -> 5745638.2 | D34: =SUM(D4:D33) -> 3010627.1 | G34: 3292687 | H34: =SUM(H4:H33) -> 5697 | I34: =SUM(I4:I33) -> 5641 | J34: =SUM(J4:J33)+(250*70) -> 2147898 | K34: =SUM(K4:K33) -> 5264 | L34: =SUM(L4:L33) -> 524613 | M34: =SUM(M4:M33) -> 343 | N34: =SUM(N4:N33) -> 34 | O34: =AVERAGE(O4:O33) -> 6.2184303 | P34: =AVERAGE(P4:P33) -> 98.713919 | Q34: =AVERAGE(Q4:Q33) -> 94.149544 | R34: =SUM(R4:R33) -> 0 | S34: =AVERAGE(S4:S33) -> 2.4006854
D36: Blended
A37: Total Units Sold | B37: =K34 -> 5264 | D37: /pc | E37: -41
A38: Total Revenue | B38: =B34 -> 5745638.2 | D38: COGS | E38: =B39/B37 -> 408.03533 | F38: 0.37
A39: COGS | B39: =J34 -> 2147898 | D39: CAC | E39: =B41/B37 -> 625.51045 | F39: 0.57
A40: Logistics | B40: =L34 -> 524613 | D40: Logistics | E40: 99 | F40: 0.09
A41: Marketing | B41: =G34 -> 3292687 | D41: AOV | E41: =B38/B37 -> 1091.4966
A42: P&L | B42: =B38-(B39+B40+B41) -> -219559.85
...

Sheet Aug 25
A1: August | B1: Shopify
A3: Products | B3: Total Dilivered Revenue | C3: Total expense | D3: Total P/L | E3: Profit % | F3: P/pcs | G3: Ad spent | H3: Total orders | I3: Shipped | J3: Total COGS | K3: Delivered | L3: Shipping charges | M3: RTO | N3: In-transit | O3: RTO% | P3: Shipped% | Q3: Delivered % | R3: CPD | S3: Cancellation % | T3: COGS/Unit
A4: V1 | B4: 942559.2 | C4: =G4+J4+L4 -> 345301 | D4: =B4-C4 -> 597258.2 | E4: =D4/B4*100 -> 63.36559 | F4: =D4/K4 -> 557.14384 | H4: 1205 | I4: 1177 | J4: =K4*T4 -> 235840 | K4: 1072 | L4: =I4*93 -> 109461 | M4: =I4-K4-N4 -> 92 | N4: 13 | O4: =M4/I4*100 -> 7.8164826 | P4: =I4/H4*100 -> 97.676349 | Q4: =K4/I4*100 -> 91.079014 | R4: =G4/K4 -> 0 | S4: =(I4-H4)/H4 -> -0.023236515 | T4: 220 | W4: Products | X4: Total Cost
A5: V1- P of 2 | B5: 63231.48 | C5: =G5+J5+L5 -> 24357 | D5: =B5-C5 -> 38874.48 | E5: =D5/B5*100 -> 61.47963 | F5: =D5/K5 -> 863.87733 | H5: 52 | I5: 49 | J5: =K5*T5 -> 19800 | K5: 45 | L5: =I5*93 -> 4557 | M5: =I5-K5-N5 -> 4 | O5: =M5/I5*100 -> 8.1632653 | P5: =I5/H5*100 -> 94.230769 | Q5: =K5/I5*100 -> 91.836735 | R5: =G5/K5 -> 0 | S5: =(I5-H5)/H5 -> -0.057692308 | T5: 440 | W5: V1 | X5: 220
A6: V2 | B6: 1349421.9 | C6: =G6+J6+L6 -> 515558 | D6: =B6-C6 -> 833863.86 | E6: =D6/B6*100 -> 61.794157 | F6: =D6/K6 -> 663.90435 | H6: 1466 | I6: 1438 | J6: =K6*T6 -> 381824 | K6: 1256 | L6: =I6*93 -> 133734 | M6: =I6-K6-N6 -> 170 | N6: 12 | O6: =M6/I6*100 -> 11.821975 | P6: =I6/H6*100 -> 98.090041 | Q6: =K6/I6*100 -> 87.343533 | R6: =G6/K6 -> 0 | S6: =(I6-H6)/H6 -> -0.019099591 | T6: 304 | W6: V2 | X6: 304
A7: V2- P of 2 | B7: 53423.07 | C7: =G7+J7+L7 -> 19814 | D7: =B7-C7 -> 33609.07 | E7: =D7/B7*100 -> 62.911154 | F7: =D7/K7 -> 1200.3239 | H7: 30 | I7: 30 | J7: =K7*T7 -> 17024 | K7: 28 | L7: =I7*93 -> 2790 | M7: =I7-K7-N7 -> 2 | O7: =M7/I7*100 -> 6.6666667 | P7: =I7/H7*100 -> 100 | Q7: =K7/I7*100 -> 93.333333 | R7: =G7/K7 -> 0 | S7: =(I7-H7)/H7 -> 0 | T7: 608 | W7: V3 | X7: 662
A8: V3 | B8: 299646.27 | C8: =G8+J8+L8 -> 165208 | D8: =B8-C8 -> 134438.27 | E8: =D8/B8*100 -> 44.865658 | F8: =D8/K8 -> 625.29428 | H8: 309 | I8: 246 | J8: =K8*T8 -> 142330 | K8: 215 | L8: =I8*93 -> 22878 | M8: =I8-K8-N8 -> 29 | N8: 2 | O8: =M8/I8*100 -> 11.788618 | P8: =I8/H8*100 -> 79.61165 | Q8: =K8/I8*100 -> 87.398374 | R8: =G8/K8 -> 0 | S8: =(I8-H8)/H8 -> -0.2038835 | T8: 662 | W8: V4 | X8: 184
A9: V4 | B9: 100529.77 | C9: =G9+J9+L9 -> 57446 | D9: =B9-C9 -> 43083.77 | E9: =D9/B9*100 -> 42.856728 | F9: =D9/K9 -> 215.41885 | H9: 227 | I9: 222 | J9: =K9*T9 -> 36800 | K9: 200 | L9: =I9*93 -> 20646 | M9: =I9-K9-N9 -> 21 | N9: 1 | O9: =M9/I9*100 -> 9.4594595 | P9: =I9/H9*100 -> 97.797357 | Q9: =K9/I9*100 -> 90.09009 | R9: =G9/K9 -> 0 | S9: =(I9-H9)/H9 -> -0.022026432 | T9: 184 | W9: V5 | X9: 206
A10: V4- P of 2 | B10: 25519.54 | C10: =G10+J10+L10 -> 15035 | D10: =B10-C10 -> 10484.54 | E10: =D10/B10*100 -> 41.084361 | F10: =D10/K10 -> 338.21097 | H10: 44 | I10: 39 | J10: =K10*T10 -> 11408 | K10: 31 | L10: =I10*93 -> 3627 | M10: =I10-K10-N10 -> 8 | O10: =M10/I10*100 -> 20.512821 | P10: =I10/H10*100 -> 88.636364 | Q10: =K10/I10*100 -> 79.487179 | R10: =G10/K10 -> 0 | S10: =(I10-H10)/H10 -> -0.11363636 | T10: 368 | W10: V6 | X10: 308
A11: V4- P of 3 | B11: 1170.23 | C11: =G11+J11+L11 -> 461 | D11: =B11-C11 -> 709.23 | E11: =D11/B11*100 -> 60.606035 | F11: =D11/K11 -> 709.23 | H11: 1 | I11: 1 | J11: =K11*T11 -> 368 | K11: 1 | L11: =I11*93 -> 93 | M11: =I11-K11-N11 -> 0 | O11: =M11/I11*100 -> 0 | P11: =I11/H11*100 -> 100 | Q11: =K11/I11*100 -> 100 | R11: =G11/K11 -> 0 | S11: =(I11-H11)/H11 -> 0 | T11: 368
A12: V5 | B12: 0 | C12: 0 | D12: 0 | E12: 0 | F12: 0 | H12: 0 | I12: 0 | J12: 0 | K12: 0 | L12: =I12*93 -> 0 | M12: =I12-K12-N12 -> 0 | S12: =(I12-H12)/H12 -> #DIV/0! | T12: 206 | W12: V7 | X12: 435
A13: V6 | B13: 1288854.1 | C13: =G13+J13+L13 -> 493116 | D13: =B13-C13 -> 795738.05 | E13: =D13/B13*100 -> 61.739966 | F13: =D13/K13 -> 666.44728 | H13: 1367 | I13: 1348 | J13: =K13*T13 -> 367752 | K13: 1194 | L13: =I13*93 -> 125364 | M13: =I13-K13-N13 -> 143 | N13: 11 | O13: =M13/I13*100 -> 10.608309 | P13: =I13/H13*100 -> 98.610095 | Q13: =K13/I13*100 -> 88.575668 | R13: =G13/K13 -> 0 | S13: =(I13-H13)/H13 -> -0.013899049 | T13: 308 | W13: V8 | X13: 699
A14: V6- P of 2 | B14: 68710.27 | C14: =G14+J14+L14 -> 27965 | D14: =B14-C14 -> 40745.27 | E14: =D14/B14*100 -> 59.300116 | F14: =D14/K14 -> 1072.2439 | H14: 49 | I14: 49 | J14: =K14*T14 -> 23408 | K14: 38 | L14: =I14*93 -> 4557 | M14: =I14-K14-N14 -> 11 | O14: =M14/I14*100 -> 22.44898 | P14: =I14/H14*100 -> 100 | Q14: =K14/I14*100 -> 77.55102 | R14: =G14/K14 -> 0 | S14: =(I14-H14)/H14 -> 0 | T14: 616 | W14: V9 | X14: 778
A15: V7 | B15: 81985.44 | C15: =G15+J15+L15 -> 39693 | D15: =B15-C15 -> 42292.44 | E15: =D15/B15*100 -> 51.585306 | F15: =D15/K15 -> 563.8992 | H15: 84 | I15: 76 | J15: =K15*T15 -> 32625 | K15: 75 | L15: =I15*93 -> 7068 | M15: =I15-K15-N15 -> 1 | O15: =M15/I15*100 -> 1.3157895 | P15: =I15/H15*100 -> 90.47619 | Q15: =K15/I15*100 -> 98.684211 | R15: =G15/K15 -> 0 | S15: =(I15-H15)/H15 -> -0.095238095 | T15: 435 | W15: V10 | X15: 1009
A16: V8 | B16: 78328.33 | C16: 0 | D16: 0 | E16: =D16/B16*100 -> 0 | F16: 0 | H16: 65 | I16: 59 | J16: 0 | K16: 55 | L16: =I16*93 -> 5487 | M16: =I16-K16-N16 -> 4 | S16: =(I16-H16)/H16 -> -0.092307692 | T16: 699
A17: V9 | B17: 1219942.1 | C17: =G17+J17+L17 -> 622983 | D17: =B17-C17 -> 596959.15 | E17: =D17/B17*100 -> 48.933398 | F17: =D17/K17 -> 846.75057 | H17: 865 | I17: 801 | J17: =K17*T17 -> 548490 | K17: 705 | L17: =I17*93 -> 74493 | M17: =I17-K17-N17 -> 91 | N17: 5 | O17: =M17/I17*100 -> 11.360799 | P17: =I17/H17*100 -> 92.601156 | Q17: =K17/I17*100 -> 88.014981 | R17: =G17/K17 -> 0 | S17: =(I17-H17)/H17 -> -0.073988439 | T17: 778
A18: V9 P of 2 | B18: 45827.25 | C18: =G18+J18+L18 -> 29868 | D18: =B18-C18 -> 15959.25 | E18: =D18/B18*100 -> 34.824804 | F18: =D18/K18 -> 886.625 | H18: 28 | I18: 20 | J18: =K18*T18 -> 28008 | K18: 18 | L18: =I18*93 -> 1860 | M18: =I18-K18-N18 -> 2 | O18: =M18/I18*100 -> 10 | P18: =I18/H18*100 -> 71.428571 | Q18: =K18/I18*100 -> 90 | R18: =G18/K18 -> 0 | S18: =(I18-H18)/H18 -> -0.28571429 | T18: 1556
A19: V10 | B19: 149456.29 | C19: =G19+J19+L19 -> 110479 | D19: =B19-C19 -> 38977.29 | E19: =D19/B19*100 -> 26.079391 | F19: =D19/K19 -> 389.7729 | H19: 123 | I19: 103 | J19: =K19*T19 -> 100900 | K19: 100 | L19: =I19*93 -> 9579 | M19: =I19-K19-N19 -> 3 | O19: =M19/I19*100 -> 2.9126214 | P19: =I19/H19*100 -> 83.739837 | Q19: =K19/I19*100 -> 97.087379 | R19: =G19/K19 -> 0 | S19: =(I19-H19)/H19 -> -0.16260163 | T19: 1009
A20: Busy Book | B20: 0 | C20: 0 | D20: 0 | E20: 0 | F20: 0 | H20: 0 | I20: 0 | J20: 0 | K20: 0 | L20: =I20*93 -> 0 | M20: =I20-K20-N20 -> 0 | O20: 0 | P20: 0 | Q20: 0 | R20: 0 | S20: =(I20-H20)/H20 -> #DIV/0! | T20: 250
A21: Busy Book Pink | B21: 120438.63 | C21: =G21+J21+L21 -> 58866 | D21: =B21-C21 -> 61572.63 | E21: =D21/B21*100 -> 51.123655 | F21: =D21/K21 -> 421.73034 | H21: 185 | I21: 162 | J21: =K21*T21 -> 43800 | K21: 146 | L21: =I21*93 -> 15066 | M21: =I21-K21-N21 -> 16 | O21: =M21/I21*100 -> 9.8765432 | P21: =I21/H21*100 -> 87.567568 | Q21: =K21/I21*100 -> 90.123457 | R21: =G21/K21 -> 0 | S21: =(I21-H21)/H21 -> -0.12432432 | T21: 300
A22: Busy Book Blue | B22: 40924.57 | C22: =G22+J22+L22 -> 18915 | D22: =B22-C22 -> 22009.57 | E22: =D22/B22*100 -> 53.780822 | F22: =D22/K22 -> 478.46891 | H22: 77 | I22: 55 | J22: =K22*T22 -> 13800 | K22: 46 | L22: =I22*93 -> 5115 | M22: =I22-K22-N22 -> 9 | O22: =M22/I22*100 -> 16.363636 | P22: =I22/H22*100 -> 71.428571 | Q22: =K22/I22*100 -> 83.636364 | R22: =G22/K22 -> 0 | S22: =(I22-H22)/H22 -> -0.28571429 | T22: 300
A23: Human Book | B23: 91236.38 | C23: =G23+J23+L23 -> 55392 | D23: =B23-C23 -> 35844.38 | E23: =D23/B23*100 -> 39.287376 | F23: =D23/K23 -> 256.03129 | H23: 249 | I23: 144 | J23: =K23*T23 -> 42000 | K23: 140 | L23: =I23*93 -> 13392 | M23: =I23-K23-N23 -> 4 | O23: =M23/I23*100 -> 2.7777778 | P23: =I23/H23*100 -> 57.831325 | Q23: =K23/I23*100 -> 97.222222 | R23: =G23/K23 -> 0 | S23: =(I23-H23)/H23 -> -0.42168675 | T23: 300
A24: V9-V3 Combo | B24: 73657.35 | C24: =G24+J24+L24 -> 39951 | D24: =B24-C24 -> 33706.35 | E24: =D24/B24*100 -> 45.761014 | F24: =D24/K24 -> 1296.3981 | H24: 48 | I24: 27 | J24: =K24*T24 -> 37440 | K24: 26 | L24: =I24*93 -> 2511 | M24: =I24-K24-N24 -> 1 | O24: =M24/I24*100 -> 3.7037037 | P24: =I24/H24*100 -> 56.25 | Q24: =K24/I24*100 -> 96.296296 | R24: =G24/K24 -> 0 | S24: =(I24-H24)/H24 -> -0.4375 | T24: 1440
A25: V9-V10 Combo | B25: 77391.53 | C25: =G25+J25+L25 -> 50946 | D25: =B25-C25 -> 26445.53 | E25: =D25/B25*100 -> 34.171091 | F25: =D25/K25 -> 979.46407 | H25: 36 | I25: 29 | J25: =K25*T25 -> 48249 | K25: 27 | L25: =I25*93 -> 2697 | M25: =I25-K25-N25 -> 2 | O25: =M25/I25*100 -> 6.8965517 | P25: =I25/H25*100 -> 80.555556 | Q25: =K25/I25*100 -> 93.103448 | R25: =G25/K25 -> 0 | S25: =(I25-H25)/H25 -> -0.19444444 | T25: 1787
A26: V7-V4 Combo | B26: 7145.28 | C26: =G26+J26+L26 -> 2848 | D26: =B26-C26 -> 4297.28 | E26: =D26/B26*100 -> 60.14152 | F26: =D26/K26 -> 1074.32 | H26: 5 | I26: 4 | J26: =K26*T26 -> 2476 | K26: 4 | L26: =I26*93 -> 372 | M26: =I26-K26-N26 -> 0 | O26: =M26/I26*100 -> 0 | P26: =I26/H26*100 -> 80 | Q26: =K26/I26*100 -> 100 | R26: =G26/K26 -> 0 | S26: =(I26-H26)/H26 -> -0.2 | T26: 619
A27: V1-V4 Combo | B27: 92452.94 | C27: =G27+J27+L27 -> 38051 | D27: =B27-C27 -> 54401.94 | E27: =D27/B27*100 -> 58.842845 | F27: =D27/K27 -> 715.815 | H27: 79 | I27: 79 | J27: =K27*T27 -> 30704 | K27: 76 | L27: =I27*93 -> 7347 | M27: =I27-K27-N27 -> 3 | O27: =M27/I27*100 -> 3.7974684 | P27: =I27/H27*100 -> 100 | Q27: =K27/I27*100 -> 96.202532 | R27: =G27/K27 -> 0 | S27: =(I27-H27)/H27 -> 0 | T27: 404
A28: V1-V7 Combo | B28: 50024.6 | C28: =G28+J28+L28 -> 19448 | D28: =B28-C28 -> 30576.6 | E28: =D28/B28*100 -> 61.123127 | F28: =D28/K28 -> 1176.0231 | H28: 28 | I28: 26 | J28: =K28*T28 -> 17030 | K28: 26 | L28: =I28*93 -> 2418 | M28: =I28-K28-N28 -> 0 | O28: =M28/I28*100 -> 0 | P28: =I28/H28*100 -> 92.857143 | Q28: =K28/I28*100 -> 100 | R28: =G28/K28 -> 0 | S28: =(I28-H28)/H28 -> -0.071428571 | T28: 655
A29: V6-V2 Combo | B29: 40157.75 | C29: =G29+J29+L29 -> 14193 | D29: =B29-C29 -> 25964.75 | E29: =D29/B29*100 -> 64.656884 | F29: =D29/K29 -> 1298.2375 | H29: 23 | I29: 21 | J29: =K29*T29 -> 12240 | K29: 20 | L29: =I29*93 -> 1953 | M29: =I29-K29-N29 -> 1 | O29: =M29/I29*100 -> 4.7619048 | P29: =I29/H29*100 -> 91.304348 | Q29: =K29/I29*100 -> 95.238095 | R29: =G29/K29 -> 0 | S29: =(I29-H29)/H29 -> -0.086956522 | T29: 612
